2025-08-13 17:29:19 | DEBUG    | __main__:<module>:68 - 调试信息
2025-08-13 17:29:19 | INFO     | __main__:<module>:69 - 普通信息
2025-08-13 17:29:19 | WARNING  | __main__:<module>:70 - 警告信息
2025-08-13 17:29:19 | ERROR    | __main__:<module>:71 - 错误信息
2025-08-13 17:29:19 | ERROR    | __main__:<module>:72 - An error has been caught in function '<module>', process 'MainProcess' (19420), thread 'MainThread' (32180):
Traceback (most recent call last):

> File "d:\wings\Documents\Github\stock_chose\packages\core\src\core\logger.py", line 72, in <module>
    test_error()
    └ <function test_error at 0x0000020475526E50>

  File "d:\wings\Documents\Github\stock_chose\packages\core\src\core\logger.py", line 64, in test_error
    1 / 0

ZeroDivisionError: division by zero
